[2025-02-23T23:42:33.196+0000] {processor.py:186} INFO - Started process (PID=81) to work on /opt/airflow/dags/etl.py
[2025-02-23T23:42:33.201+0000] {processor.py:914} INFO - Processing file /opt/airflow/dags/etl.py for tasks to queue
[2025-02-23T23:42:33.211+0000] {logging_mixin.py:190} INFO - [2025-02-23T23:42:33.210+0000] {dagbag.py:588} INFO - Filling up the DagBag from /opt/airflow/dags/etl.py
[2025-02-23T23:42:45.813+0000] {logging_mixin.py:190} INFO - [2025-02-23T23:42:45.752+0000] {dagbag.py:387} ERROR - Failed to import: /opt/airflow/dags/etl.py
Traceback (most recent call last):
  File "/home/airflow/.local/lib/python3.12/site-packages/airflow/models/dagbag.py", line 383, in parse
    loader.exec_module(new_module)
  File "<frozen importlib._bootstrap_external>", line 999, in exec_module
  File "<frozen importlib._bootstrap>", line 488, in _call_with_frames_removed
  File "/opt/airflow/dags/etl.py", line 69, in <module>
    dag = DAG(
          ^^^^
TypeError: DAG.__init__() got an unexpected keyword argument 'catch_up'
[2025-02-23T23:42:45.860+0000] {processor.py:927} WARNING - No viable dags retrieved from /opt/airflow/dags/etl.py
[2025-02-23T23:42:47.157+0000] {processor.py:208} INFO - Processing /opt/airflow/dags/etl.py took 14.043 seconds
[2025-02-23T23:44:21.701+0000] {processor.py:186} INFO - Started process (PID=159) to work on /opt/airflow/dags/etl.py
[2025-02-23T23:44:21.723+0000] {processor.py:914} INFO - Processing file /opt/airflow/dags/etl.py for tasks to queue
[2025-02-23T23:44:21.727+0000] {logging_mixin.py:190} INFO - [2025-02-23T23:44:21.726+0000] {dagbag.py:588} INFO - Filling up the DagBag from /opt/airflow/dags/etl.py
[2025-02-23T23:44:21.995+0000] {logging_mixin.py:190} INFO - [2025-02-23T23:44:21.983+0000] {dagbag.py:387} ERROR - Failed to import: /opt/airflow/dags/etl.py
Traceback (most recent call last):
  File "/home/airflow/.local/lib/python3.12/site-packages/airflow/models/dagbag.py", line 383, in parse
    loader.exec_module(new_module)
  File "<frozen importlib._bootstrap_external>", line 999, in exec_module
  File "<frozen importlib._bootstrap>", line 488, in _call_with_frames_removed
  File "/opt/airflow/dags/etl.py", line 69, in <module>
    dag = DAG(
          ^^^^
TypeError: DAG.__init__() got an unexpected keyword argument 'catch_up'
[2025-02-23T23:44:21.999+0000] {processor.py:927} WARNING - No viable dags retrieved from /opt/airflow/dags/etl.py
[2025-02-23T23:44:22.041+0000] {processor.py:208} INFO - Processing /opt/airflow/dags/etl.py took 0.354 seconds
[2025-02-23T23:44:53.355+0000] {processor.py:186} INFO - Started process (PID=207) to work on /opt/airflow/dags/etl.py
[2025-02-23T23:44:53.357+0000] {processor.py:914} INFO - Processing file /opt/airflow/dags/etl.py for tasks to queue
[2025-02-23T23:44:53.360+0000] {logging_mixin.py:190} INFO - [2025-02-23T23:44:53.359+0000] {dagbag.py:588} INFO - Filling up the DagBag from /opt/airflow/dags/etl.py
[2025-02-23T23:44:53.620+0000] {logging_mixin.py:190} INFO - [2025-02-23T23:44:53.612+0000] {dagbag.py:387} ERROR - Failed to import: /opt/airflow/dags/etl.py
Traceback (most recent call last):
  File "/home/airflow/.local/lib/python3.12/site-packages/airflow/models/dagbag.py", line 383, in parse
    loader.exec_module(new_module)
  File "<frozen importlib._bootstrap_external>", line 999, in exec_module
  File "<frozen importlib._bootstrap>", line 488, in _call_with_frames_removed
  File "/opt/airflow/dags/etl.py", line 69, in <module>
    dag = DAG(
          ^^^^
TypeError: DAG.__init__() got an unexpected keyword argument 'catch_up'
[2025-02-23T23:44:53.623+0000] {processor.py:927} WARNING - No viable dags retrieved from /opt/airflow/dags/etl.py
[2025-02-23T23:44:53.684+0000] {processor.py:208} INFO - Processing /opt/airflow/dags/etl.py took 0.343 seconds
[2025-02-23T23:45:24.010+0000] {processor.py:186} INFO - Started process (PID=268) to work on /opt/airflow/dags/etl.py
[2025-02-23T23:45:24.016+0000] {processor.py:914} INFO - Processing file /opt/airflow/dags/etl.py for tasks to queue
[2025-02-23T23:45:24.025+0000] {logging_mixin.py:190} INFO - [2025-02-23T23:45:24.021+0000] {dagbag.py:588} INFO - Filling up the DagBag from /opt/airflow/dags/etl.py
[2025-02-23T23:45:25.556+0000] {logging_mixin.py:190} INFO - [2025-02-23T23:45:25.537+0000] {dagbag.py:387} ERROR - Failed to import: /opt/airflow/dags/etl.py
Traceback (most recent call last):
  File "/home/airflow/.local/lib/python3.12/site-packages/airflow/models/dagbag.py", line 383, in parse
    loader.exec_module(new_module)
  File "<frozen importlib._bootstrap_external>", line 999, in exec_module
  File "<frozen importlib._bootstrap>", line 488, in _call_with_frames_removed
  File "/opt/airflow/dags/etl.py", line 69, in <module>
    dag = DAG(
          ^^^^
TypeError: DAG.__init__() got an unexpected keyword argument 'catch_up'
[2025-02-23T23:45:25.560+0000] {processor.py:927} WARNING - No viable dags retrieved from /opt/airflow/dags/etl.py
[2025-02-23T23:45:25.700+0000] {processor.py:208} INFO - Processing /opt/airflow/dags/etl.py took 1.736 seconds
[2025-02-23T23:45:55.937+0000] {processor.py:186} INFO - Started process (PID=333) to work on /opt/airflow/dags/etl.py
[2025-02-23T23:45:55.947+0000] {processor.py:914} INFO - Processing file /opt/airflow/dags/etl.py for tasks to queue
[2025-02-23T23:45:55.956+0000] {logging_mixin.py:190} INFO - [2025-02-23T23:45:55.954+0000] {dagbag.py:588} INFO - Filling up the DagBag from /opt/airflow/dags/etl.py
[2025-02-23T23:45:56.135+0000] {logging_mixin.py:190} INFO - [2025-02-23T23:45:56.125+0000] {dagbag.py:387} ERROR - Failed to import: /opt/airflow/dags/etl.py
Traceback (most recent call last):
  File "/home/airflow/.local/lib/python3.12/site-packages/airflow/models/dagbag.py", line 383, in parse
    loader.exec_module(new_module)
  File "<frozen importlib._bootstrap_external>", line 999, in exec_module
  File "<frozen importlib._bootstrap>", line 488, in _call_with_frames_removed
  File "/opt/airflow/dags/etl.py", line 69, in <module>
    dag = DAG(
          ^^^^
TypeError: DAG.__init__() got an unexpected keyword argument 'catch_up'
[2025-02-23T23:45:56.138+0000] {processor.py:927} WARNING - No viable dags retrieved from /opt/airflow/dags/etl.py
[2025-02-23T23:45:56.188+0000] {processor.py:208} INFO - Processing /opt/airflow/dags/etl.py took 0.298 seconds
[2025-02-23T23:46:30.026+0000] {processor.py:186} INFO - Started process (PID=396) to work on /opt/airflow/dags/etl.py
[2025-02-23T23:46:30.030+0000] {processor.py:914} INFO - Processing file /opt/airflow/dags/etl.py for tasks to queue
[2025-02-23T23:46:30.036+0000] {logging_mixin.py:190} INFO - [2025-02-23T23:46:30.034+0000] {dagbag.py:588} INFO - Filling up the DagBag from /opt/airflow/dags/etl.py
[2025-02-23T23:46:30.255+0000] {logging_mixin.py:190} INFO - [2025-02-23T23:46:30.245+0000] {dagbag.py:387} ERROR - Failed to import: /opt/airflow/dags/etl.py
Traceback (most recent call last):
  File "/home/airflow/.local/lib/python3.12/site-packages/airflow/models/dagbag.py", line 383, in parse
    loader.exec_module(new_module)
  File "<frozen importlib._bootstrap_external>", line 999, in exec_module
  File "<frozen importlib._bootstrap>", line 488, in _call_with_frames_removed
  File "/opt/airflow/dags/etl.py", line 69, in <module>
    dag = DAG(
          ^^^^
TypeError: DAG.__init__() got an unexpected keyword argument 'catch_up'
[2025-02-23T23:46:30.258+0000] {processor.py:927} WARNING - No viable dags retrieved from /opt/airflow/dags/etl.py
[2025-02-23T23:46:30.301+0000] {processor.py:208} INFO - Processing /opt/airflow/dags/etl.py took 0.299 seconds
[2025-02-23T23:47:03.016+0000] {processor.py:186} INFO - Started process (PID=460) to work on /opt/airflow/dags/etl.py
[2025-02-23T23:47:03.022+0000] {processor.py:914} INFO - Processing file /opt/airflow/dags/etl.py for tasks to queue
[2025-02-23T23:47:03.031+0000] {logging_mixin.py:190} INFO - [2025-02-23T23:47:03.028+0000] {dagbag.py:588} INFO - Filling up the DagBag from /opt/airflow/dags/etl.py
[2025-02-23T23:47:03.201+0000] {logging_mixin.py:190} INFO - [2025-02-23T23:47:03.193+0000] {dagbag.py:387} ERROR - Failed to import: /opt/airflow/dags/etl.py
Traceback (most recent call last):
  File "/home/airflow/.local/lib/python3.12/site-packages/airflow/models/dagbag.py", line 383, in parse
    loader.exec_module(new_module)
  File "<frozen importlib._bootstrap_external>", line 999, in exec_module
  File "<frozen importlib._bootstrap>", line 488, in _call_with_frames_removed
  File "/opt/airflow/dags/etl.py", line 69, in <module>
    dag = DAG(
          ^^^^
TypeError: DAG.__init__() got an unexpected keyword argument 'catch_up'
[2025-02-23T23:47:03.205+0000] {processor.py:927} WARNING - No viable dags retrieved from /opt/airflow/dags/etl.py
[2025-02-23T23:47:03.247+0000] {processor.py:208} INFO - Processing /opt/airflow/dags/etl.py took 0.278 seconds
[2025-02-23T23:47:34.104+0000] {processor.py:186} INFO - Started process (PID=521) to work on /opt/airflow/dags/etl.py
[2025-02-23T23:47:34.106+0000] {processor.py:914} INFO - Processing file /opt/airflow/dags/etl.py for tasks to queue
[2025-02-23T23:47:34.109+0000] {logging_mixin.py:190} INFO - [2025-02-23T23:47:34.109+0000] {dagbag.py:588} INFO - Filling up the DagBag from /opt/airflow/dags/etl.py
[2025-02-23T23:47:34.326+0000] {logging_mixin.py:190} INFO - [2025-02-23T23:47:34.315+0000] {dagbag.py:387} ERROR - Failed to import: /opt/airflow/dags/etl.py
Traceback (most recent call last):
  File "/home/airflow/.local/lib/python3.12/site-packages/airflow/models/dagbag.py", line 383, in parse
    loader.exec_module(new_module)
  File "<frozen importlib._bootstrap_external>", line 999, in exec_module
  File "<frozen importlib._bootstrap>", line 488, in _call_with_frames_removed
  File "/opt/airflow/dags/etl.py", line 69, in <module>
    dag = DAG(
          ^^^^
TypeError: DAG.__init__() got an unexpected keyword argument 'catch_up'
[2025-02-23T23:47:34.328+0000] {processor.py:927} WARNING - No viable dags retrieved from /opt/airflow/dags/etl.py
[2025-02-23T23:47:34.363+0000] {processor.py:208} INFO - Processing /opt/airflow/dags/etl.py took 0.277 seconds
[2025-02-23T23:48:05.050+0000] {processor.py:186} INFO - Started process (PID=583) to work on /opt/airflow/dags/etl.py
[2025-02-23T23:48:05.053+0000] {processor.py:914} INFO - Processing file /opt/airflow/dags/etl.py for tasks to queue
[2025-02-23T23:48:05.059+0000] {logging_mixin.py:190} INFO - [2025-02-23T23:48:05.058+0000] {dagbag.py:588} INFO - Filling up the DagBag from /opt/airflow/dags/etl.py
[2025-02-23T23:48:05.356+0000] {logging_mixin.py:190} INFO - [2025-02-23T23:48:05.346+0000] {dagbag.py:387} ERROR - Failed to import: /opt/airflow/dags/etl.py
Traceback (most recent call last):
  File "/home/airflow/.local/lib/python3.12/site-packages/airflow/models/dagbag.py", line 383, in parse
    loader.exec_module(new_module)
  File "<frozen importlib._bootstrap_external>", line 999, in exec_module
  File "<frozen importlib._bootstrap>", line 488, in _call_with_frames_removed
  File "/opt/airflow/dags/etl.py", line 69, in <module>
    dag = DAG(
          ^^^^
TypeError: DAG.__init__() got an unexpected keyword argument 'catch_up'
[2025-02-23T23:48:05.361+0000] {processor.py:927} WARNING - No viable dags retrieved from /opt/airflow/dags/etl.py
[2025-02-23T23:48:05.483+0000] {processor.py:208} INFO - Processing /opt/airflow/dags/etl.py took 0.476 seconds
[2025-02-23T23:48:35.939+0000] {processor.py:186} INFO - Started process (PID=641) to work on /opt/airflow/dags/etl.py
[2025-02-23T23:48:35.944+0000] {processor.py:914} INFO - Processing file /opt/airflow/dags/etl.py for tasks to queue
[2025-02-23T23:48:35.950+0000] {logging_mixin.py:190} INFO - [2025-02-23T23:48:35.949+0000] {dagbag.py:588} INFO - Filling up the DagBag from /opt/airflow/dags/etl.py
[2025-02-23T23:48:36.304+0000] {logging_mixin.py:190} INFO - [2025-02-23T23:48:36.299+0000] {dagbag.py:387} ERROR - Failed to import: /opt/airflow/dags/etl.py
Traceback (most recent call last):
  File "/home/airflow/.local/lib/python3.12/site-packages/airflow/models/dagbag.py", line 383, in parse
    loader.exec_module(new_module)
  File "<frozen importlib._bootstrap_external>", line 999, in exec_module
  File "<frozen importlib._bootstrap>", line 488, in _call_with_frames_removed
  File "/opt/airflow/dags/etl.py", line 69, in <module>
    dag = DAG(
          ^^^^
TypeError: DAG.__init__() got an unexpected keyword argument 'catch_up'
[2025-02-23T23:48:36.308+0000] {processor.py:927} WARNING - No viable dags retrieved from /opt/airflow/dags/etl.py
[2025-02-23T23:48:36.354+0000] {processor.py:208} INFO - Processing /opt/airflow/dags/etl.py took 0.443 seconds
[2025-02-23T23:49:06.679+0000] {processor.py:186} INFO - Started process (PID=704) to work on /opt/airflow/dags/etl.py
[2025-02-23T23:49:06.681+0000] {processor.py:914} INFO - Processing file /opt/airflow/dags/etl.py for tasks to queue
[2025-02-23T23:49:06.683+0000] {logging_mixin.py:190} INFO - [2025-02-23T23:49:06.683+0000] {dagbag.py:588} INFO - Filling up the DagBag from /opt/airflow/dags/etl.py
[2025-02-23T23:49:06.820+0000] {logging_mixin.py:190} INFO - [2025-02-23T23:49:06.813+0000] {dagbag.py:387} ERROR - Failed to import: /opt/airflow/dags/etl.py
Traceback (most recent call last):
  File "/home/airflow/.local/lib/python3.12/site-packages/airflow/models/dagbag.py", line 383, in parse
    loader.exec_module(new_module)
  File "<frozen importlib._bootstrap_external>", line 999, in exec_module
  File "<frozen importlib._bootstrap>", line 488, in _call_with_frames_removed
  File "/opt/airflow/dags/etl.py", line 69, in <module>
    dag = DAG(
          ^^^^
TypeError: DAG.__init__() got an unexpected keyword argument 'catch_up'
[2025-02-23T23:49:06.822+0000] {processor.py:927} WARNING - No viable dags retrieved from /opt/airflow/dags/etl.py
[2025-02-23T23:49:06.857+0000] {processor.py:208} INFO - Processing /opt/airflow/dags/etl.py took 0.192 seconds
[2025-02-23T23:49:38.051+0000] {processor.py:186} INFO - Started process (PID=765) to work on /opt/airflow/dags/etl.py
[2025-02-23T23:49:38.057+0000] {processor.py:914} INFO - Processing file /opt/airflow/dags/etl.py for tasks to queue
[2025-02-23T23:49:38.063+0000] {logging_mixin.py:190} INFO - [2025-02-23T23:49:38.062+0000] {dagbag.py:588} INFO - Filling up the DagBag from /opt/airflow/dags/etl.py
[2025-02-23T23:49:38.317+0000] {logging_mixin.py:190} INFO - [2025-02-23T23:49:38.310+0000] {dagbag.py:387} ERROR - Failed to import: /opt/airflow/dags/etl.py
Traceback (most recent call last):
  File "/home/airflow/.local/lib/python3.12/site-packages/airflow/models/dagbag.py", line 383, in parse
    loader.exec_module(new_module)
  File "<frozen importlib._bootstrap_external>", line 999, in exec_module
  File "<frozen importlib._bootstrap>", line 488, in _call_with_frames_removed
  File "/opt/airflow/dags/etl.py", line 69, in <module>
    dag = DAG(
          ^^^^
TypeError: DAG.__init__() got an unexpected keyword argument 'catch_up'
[2025-02-23T23:49:38.320+0000] {processor.py:927} WARNING - No viable dags retrieved from /opt/airflow/dags/etl.py
[2025-02-23T23:49:38.358+0000] {processor.py:208} INFO - Processing /opt/airflow/dags/etl.py took 0.346 seconds
[2025-02-23T23:50:09.019+0000] {processor.py:186} INFO - Started process (PID=829) to work on /opt/airflow/dags/etl.py
[2025-02-23T23:50:09.022+0000] {processor.py:914} INFO - Processing file /opt/airflow/dags/etl.py for tasks to queue
[2025-02-23T23:50:09.029+0000] {logging_mixin.py:190} INFO - [2025-02-23T23:50:09.028+0000] {dagbag.py:588} INFO - Filling up the DagBag from /opt/airflow/dags/etl.py
[2025-02-23T23:50:09.251+0000] {logging_mixin.py:190} INFO - [2025-02-23T23:50:09.241+0000] {dagbag.py:387} ERROR - Failed to import: /opt/airflow/dags/etl.py
Traceback (most recent call last):
  File "/home/airflow/.local/lib/python3.12/site-packages/airflow/models/dagbag.py", line 383, in parse
    loader.exec_module(new_module)
  File "<frozen importlib._bootstrap_external>", line 999, in exec_module
  File "<frozen importlib._bootstrap>", line 488, in _call_with_frames_removed
  File "/opt/airflow/dags/etl.py", line 69, in <module>
    dag = DAG(
          ^^^^
TypeError: DAG.__init__() got an unexpected keyword argument 'catch_up'
[2025-02-23T23:50:09.254+0000] {processor.py:927} WARNING - No viable dags retrieved from /opt/airflow/dags/etl.py
[2025-02-23T23:50:09.289+0000] {processor.py:208} INFO - Processing /opt/airflow/dags/etl.py took 0.289 seconds
[2025-02-23T23:50:39.723+0000] {processor.py:186} INFO - Started process (PID=890) to work on /opt/airflow/dags/etl.py
[2025-02-23T23:50:39.726+0000] {processor.py:914} INFO - Processing file /opt/airflow/dags/etl.py for tasks to queue
[2025-02-23T23:50:39.729+0000] {logging_mixin.py:190} INFO - [2025-02-23T23:50:39.728+0000] {dagbag.py:588} INFO - Filling up the DagBag from /opt/airflow/dags/etl.py
[2025-02-23T23:50:39.909+0000] {logging_mixin.py:190} INFO - [2025-02-23T23:50:39.900+0000] {dagbag.py:387} ERROR - Failed to import: /opt/airflow/dags/etl.py
Traceback (most recent call last):
  File "/home/airflow/.local/lib/python3.12/site-packages/airflow/models/dagbag.py", line 383, in parse
    loader.exec_module(new_module)
  File "<frozen importlib._bootstrap_external>", line 999, in exec_module
  File "<frozen importlib._bootstrap>", line 488, in _call_with_frames_removed
  File "/opt/airflow/dags/etl.py", line 69, in <module>
    dag = DAG(
          ^^^^
TypeError: DAG.__init__() got an unexpected keyword argument 'catch_up'
[2025-02-23T23:50:39.912+0000] {processor.py:927} WARNING - No viable dags retrieved from /opt/airflow/dags/etl.py
[2025-02-23T23:50:39.957+0000] {processor.py:208} INFO - Processing /opt/airflow/dags/etl.py took 0.253 seconds
[2025-02-23T23:51:10.948+0000] {processor.py:186} INFO - Started process (PID=953) to work on /opt/airflow/dags/etl.py
[2025-02-23T23:51:10.953+0000] {processor.py:914} INFO - Processing file /opt/airflow/dags/etl.py for tasks to queue
[2025-02-23T23:51:10.961+0000] {logging_mixin.py:190} INFO - [2025-02-23T23:51:10.958+0000] {dagbag.py:588} INFO - Filling up the DagBag from /opt/airflow/dags/etl.py
[2025-02-23T23:51:11.313+0000] {logging_mixin.py:190} INFO - [2025-02-23T23:51:11.301+0000] {dagbag.py:387} ERROR - Failed to import: /opt/airflow/dags/etl.py
Traceback (most recent call last):
  File "/home/airflow/.local/lib/python3.12/site-packages/airflow/models/dagbag.py", line 383, in parse
    loader.exec_module(new_module)
  File "<frozen importlib._bootstrap_external>", line 999, in exec_module
  File "<frozen importlib._bootstrap>", line 488, in _call_with_frames_removed
  File "/opt/airflow/dags/etl.py", line 69, in <module>
    dag = DAG(
          ^^^^
TypeError: DAG.__init__() got an unexpected keyword argument 'catch_up'
[2025-02-23T23:51:11.317+0000] {processor.py:927} WARNING - No viable dags retrieved from /opt/airflow/dags/etl.py
[2025-02-23T23:51:11.383+0000] {processor.py:208} INFO - Processing /opt/airflow/dags/etl.py took 0.463 seconds
[2025-02-23T23:57:49.250+0000] {processor.py:186} INFO - Started process (PID=69) to work on /opt/airflow/dags/etl.py
[2025-02-23T23:57:49.332+0000] {processor.py:914} INFO - Processing file /opt/airflow/dags/etl.py for tasks to queue
[2025-02-23T23:57:49.414+0000] {logging_mixin.py:190} INFO - [2025-02-23T23:57:49.412+0000] {dagbag.py:588} INFO - Filling up the DagBag from /opt/airflow/dags/etl.py
[2025-02-23T23:57:52.128+0000] {logging_mixin.py:190} INFO - [2025-02-23T23:57:52.057+0000] {dagbag.py:387} ERROR - Failed to import: /opt/airflow/dags/etl.py
Traceback (most recent call last):
  File "/home/airflow/.local/lib/python3.12/site-packages/airflow/models/dagbag.py", line 383, in parse
    loader.exec_module(new_module)
  File "<frozen importlib._bootstrap_external>", line 999, in exec_module
  File "<frozen importlib._bootstrap>", line 488, in _call_with_frames_removed
  File "/opt/airflow/dags/etl.py", line 69, in <module>
    dag = DAG(
          ^^^^
TypeError: DAG.__init__() got an unexpected keyword argument 'catch_up'
[2025-02-23T23:57:52.132+0000] {processor.py:927} WARNING - No viable dags retrieved from /opt/airflow/dags/etl.py
[2025-02-23T23:57:52.389+0000] {processor.py:208} INFO - Processing /opt/airflow/dags/etl.py took 3.221 seconds
[2025-02-23T23:58:34.135+0000] {processor.py:186} INFO - Started process (PID=139) to work on /opt/airflow/dags/etl.py
[2025-02-23T23:58:34.145+0000] {processor.py:914} INFO - Processing file /opt/airflow/dags/etl.py for tasks to queue
[2025-02-23T23:58:34.150+0000] {logging_mixin.py:190} INFO - [2025-02-23T23:58:34.149+0000] {dagbag.py:588} INFO - Filling up the DagBag from /opt/airflow/dags/etl.py
[2025-02-23T23:58:34.369+0000] {logging_mixin.py:190} INFO - [2025-02-23T23:58:34.357+0000] {dagbag.py:387} ERROR - Failed to import: /opt/airflow/dags/etl.py
Traceback (most recent call last):
  File "/home/airflow/.local/lib/python3.12/site-packages/airflow/models/dagbag.py", line 383, in parse
    loader.exec_module(new_module)
  File "<frozen importlib._bootstrap_external>", line 999, in exec_module
  File "<frozen importlib._bootstrap>", line 488, in _call_with_frames_removed
  File "/opt/airflow/dags/etl.py", line 69, in <module>
    dag = DAG(
          ^^^^
TypeError: DAG.__init__() got an unexpected keyword argument 'catch_up'
[2025-02-23T23:58:34.371+0000] {processor.py:927} WARNING - No viable dags retrieved from /opt/airflow/dags/etl.py
[2025-02-23T23:58:34.411+0000] {processor.py:208} INFO - Processing /opt/airflow/dags/etl.py took 0.287 seconds
[2025-02-23T23:59:05.307+0000] {processor.py:186} INFO - Started process (PID=187) to work on /opt/airflow/dags/etl.py
[2025-02-23T23:59:05.311+0000] {processor.py:914} INFO - Processing file /opt/airflow/dags/etl.py for tasks to queue
[2025-02-23T23:59:05.323+0000] {logging_mixin.py:190} INFO - [2025-02-23T23:59:05.321+0000] {dagbag.py:588} INFO - Filling up the DagBag from /opt/airflow/dags/etl.py
[2025-02-23T23:59:05.692+0000] {logging_mixin.py:190} INFO - [2025-02-23T23:59:05.684+0000] {dagbag.py:387} ERROR - Failed to import: /opt/airflow/dags/etl.py
Traceback (most recent call last):
  File "/home/airflow/.local/lib/python3.12/site-packages/airflow/models/dagbag.py", line 383, in parse
    loader.exec_module(new_module)
  File "<frozen importlib._bootstrap_external>", line 999, in exec_module
  File "<frozen importlib._bootstrap>", line 488, in _call_with_frames_removed
  File "/opt/airflow/dags/etl.py", line 69, in <module>
    dag = DAG(
          ^^^^
TypeError: DAG.__init__() got an unexpected keyword argument 'catch_up'
[2025-02-23T23:59:05.695+0000] {processor.py:927} WARNING - No viable dags retrieved from /opt/airflow/dags/etl.py
[2025-02-23T23:59:05.736+0000] {processor.py:208} INFO - Processing /opt/airflow/dags/etl.py took 0.466 seconds
[2025-02-23T23:59:37.433+0000] {processor.py:186} INFO - Started process (PID=251) to work on /opt/airflow/dags/etl.py
[2025-02-23T23:59:37.441+0000] {processor.py:914} INFO - Processing file /opt/airflow/dags/etl.py for tasks to queue
[2025-02-23T23:59:37.460+0000] {logging_mixin.py:190} INFO - [2025-02-23T23:59:37.458+0000] {dagbag.py:588} INFO - Filling up the DagBag from /opt/airflow/dags/etl.py
[2025-02-23T23:59:37.860+0000] {logging_mixin.py:190} INFO - [2025-02-23T23:59:37.853+0000] {dagbag.py:387} ERROR - Failed to import: /opt/airflow/dags/etl.py
Traceback (most recent call last):
  File "/home/airflow/.local/lib/python3.12/site-packages/airflow/models/dagbag.py", line 383, in parse
    loader.exec_module(new_module)
  File "<frozen importlib._bootstrap_external>", line 999, in exec_module
  File "<frozen importlib._bootstrap>", line 488, in _call_with_frames_removed
  File "/opt/airflow/dags/etl.py", line 69, in <module>
    dag = DAG(
          ^^^^
TypeError: DAG.__init__() got an unexpected keyword argument 'catch_up'
[2025-02-23T23:59:37.865+0000] {processor.py:927} WARNING - No viable dags retrieved from /opt/airflow/dags/etl.py
[2025-02-23T23:59:37.916+0000] {processor.py:208} INFO - Processing /opt/airflow/dags/etl.py took 0.513 seconds
